Workbook

Sheet T0 aggregated CIS
A1: Batch 6 | C1: Batch 8 | E1: Batch 3 | G1: Batch 4 | L1: Batch 3 | M1: Batch 4 | N1: Batch 6 | O1: Batch 8
A2: Strain | B2: T0 | C2: Strain | D2: T0 | E2: Strain | F2: Freq | G2: Strain | H2: Freq | K2: Strain | L2: Chr III | M2: Chr VII | N2: Chr IV | O2: Chr XV
A3: DSB2_Chr4 | B3: 42.196442 | C3: DSB2_Chr15 | D3: 54.813711 | E3: DSB2_Chr3 | F3: 6.9941328 | G3: DSB2_Chr7 | H3: 46.943666 | K3: DSB2_Locus | L3: 6.9941328 | M3: 46.943666 | N3: 42.196442 | O3: 54.813711
A4: DSB1_Chr3_L02 | B4: 3.3285624 | C4: DSB1_Chr3_L02 | D4: 2.8677044 | E4: Chr3_L02 | F4: 15.385546 | G4: Chr3_L02 | H4: 2.7809512 | K4: DSB1_Chr3_L02 | L4: 15.385546 | M4: 2.7809512 | N4: 3.3285624 | O4: 2.8677044
A5: DSB1_Chr3_L03 | B5: 1.390571 | C5: DSB1_Chr3_L03 | D5: 1.7831124 | E5: Chr3_L03 | F5: 0.0095784716 | G5: Chr3_L04 | H5: 3.9968283 | K5: DSB1_Chr3_L03 | L5: 0.0095784716 | M5: 3.9968283 | N5: 1.390571 | O5: 1.7831124
A6: DSB1_Chr3_L04 | B6: 13.596665 | C6: DSB1_Chr3_L04 | D6: 4.6254207 | K6: DSB1_Chr3_L04 | N6: 13.596665 | O6: 4.6254207
A7: DSB1_Chr4_L01 | B7: 1.9630837 | C7: DSB1_Chr4_L01 | D7: 1.5455693 | E7: Chr4_L01 | F7: 7.793347 | G7: Chr4_L01 | H7: 1.6893326 | K7: DSB1_Chr4_L01 | L7: 7.793347 | M7: 1.6893326 | N7: 1.9630837 | O7: 1.5455693
A8: DSB1_Chr4_L03 | B8: 2.0777911 | C8: DSB1_Chr4_L03 | D8: 2.9836542 | E8: Chr4_L03 | F8: 8.5066911 | G8: Chr4_L03 | H8: 2.0251751 | K8: DSB1_Chr4_L03 | L8: 8.5066911 | M8: 2.0251751 | N8: 2.0777911 | O8: 2.9836542
A9: DSB1_Chr4_L06_2 | B9: 1.9400398 | C9: DSB1_Chr4_L06_2 | D9: 1.4126888 | E9: Chr4_L06_2 | F9: 7.7813319 | G9: Chr4_L06_2 | H9: 1.9192789 | K9: DSB1_Chr4_L06_2 | L9: 7.7813319 | M9: 1.9192789 | N9: 1.9400398 | O9: 1.4126888
A10: DSB1_Chr4_L10_2 | B10: 1.9423442 | C10: DSB1_Chr4_L10_2 | D10: 1.8408307 | E10: Chr4_L10_2 | F10: 6.747193 | G10: Chr4_L10_2 | H10: 4.7176534 | K10: DSB1_Chr4_L10_2 | L10: 6.747193 | M10: 4.7176534 | N10: 1.9423442 | O10: 1.8408307
A11: DSB1_Chr4_L12_2 | B11: 2.3115586 | C11: DSB1_Chr4_L12_2 | D11: 1.5093991 | E11: Chr4_L12_2 | F11: 8.6009634 | G11: Chr4_L12_2 | H11: 2.3574704 | K11: DSB1_Chr4_L12_2 | L11: 8.6009634 | M11: 2.3574704 | N11: 2.3115586 | O11: 1.5093991
A12: DSB1_Chr4_L13 | B12: 1.2197901 | C12: DSB1_Chr4_L13 | D12: 1.3434268 | G12: Chr4_L13 | H12: 2.0564745 | K12: DSB1_Chr4_L13 | M12: 2.0564745 | N12: 1.2197901 | O12: 1.3434268
A13: DSB1_Chr4_L15_2 | B13: 1.8829421 | C13: DSB1_Chr4_L15_2 | D13: 1.0196909 | E13: Chr4_L15_2 | F13: 4.9636648 | G13: Chr4_L15_2 | H13: 2.2604423 | K13: DSB1_Chr4_L15_2 | L13: 4.9636648 | M13: 2.2604423 | N13: 1.8829421 | O13: 1.0196909
A14: DSB1_Chr7_990K | B14: 2.0396406 | C14: DSB1_Chr7_990K | D14: 1.0225127 | E14: Chr7_990K | F14: 2.5917328 | G14: Chr7_990K | H14: 1.6063892 | K14: DSB1_Chr7_990K | L14: 2.5917328 | M14: 1.6063892 | N14: 2.0396406 | O14: 1.0225127
A15: DSB1_Chr7_L03 | B15: 1.0049698 | C15: DSB1_Chr7_L03 | D15: 1.6291968 | G15: Chr7_L03 | H15: 2.598893 | K15: DSB1_Chr7_L03 | M15: 2.598893 | N15: 1.0049698 | O15: 1.6291968
A16: DSB1_Chr7_L06 | B16: 1.5016937 | C16: DSB1_Chr7_L06 | D16: 2.5573079 | E16: Chr7_L06 | F16: 0.18879672 | G16: Chr7_L06 | H16: 2.85993 | K16: DSB1_Chr7_L06 | L16: 0.18879672 | M16: 2.85993 | N16: 1.5016937 | O16: 2.5573079
A17: DSB1_Chr7_L09 | B17: 1.9935528 | C17: DSB1_Chr7_L09 | D17: 1.8285175 | G17: Chr7_L09 | H17: 2.0321653 | K17: DSB1_Chr7_L09 | M17: 2.0321653 | N17: 1.9935528 | O17: 1.8285175
A18: DSB1_Chr12_L01 | B18: 1.8499126 | C18: DSB1_Chr12_L01 | D18: 1.8354437 | E18: Chr12_L01 | F18: 1.4163535 | G18: Chr12_L01 | H18: 2.4409354 | K18: DSB1_Chr12_L01 | L18: 1.4163535 | M18: 2.4409354 | N18: 1.8499126 | O18: 1.8354437
A19: DSB1_Chr12_L05 | B19: 4.2067908 | C19: DSB1_Chr12_L05 | D19: 0.76906501 | E19: Chr12_L05 | F19: 8.2247983 | G19: Chr12_L05 | H19: 1.5763418 | K19: DSB1_Chr12_L05 | L19: 8.2247983 | M19: 1.5763418 | N19: 4.2067908 | O19: 0.76906501
A20: DSB1_Chr12_L07 | B20: 1.6112802 | C20: DSB1_Chr12_L07 | D20: 1.2633907 | E20: Chr12_L07 | F20: 1.0729569 | G20: Chr12_L07 | H20: 2.0309134 | K20: DSB1_Chr12_L07 | L20: 1.0729569 | M20: 2.0309134 | N20: 1.6112802 | O20: 1.2633907
A21: DSB1_Chr12_L12 | B21: 1.5229453 | C21: DSB1_Chr12_L12 | D21: 2.4487974 | E21: Chr12_L12 | F21: 1.2457895 | G21: Chr12_L12 | H21: 2.3763544 | K21: DSB1_Chr12_L12 | L21: 1.2457895 | M21: 2.3763544 | N21: 1.5229453 | O21: 2.4487974
A22: DSB1_Chr15_L01 | B22: 2.0875207 | C22: DSB1_Chr15_L01 | D22: 2.9259358 | E22: Chr15_L01 | F22: 8.3881365 | G22: Chr15_L01 | H22: 2.9047925 | K22: DSB1_Chr15_L01 | L22: 8.3881365 | M22: 2.9047925 | N22: 2.0875207 | O22: 2.9259358
A23: DSB1_Chr15_L04 | B23: 0.0053769085 | C23: DSB1_Chr15_L04 | D23: 0.0053870465 | E23: Chr15_L04 | F23: 0.0062176044 | K23: DSB1_Chr15_L04 | L23: 0.0062176044 | N23: 0.0053769085 | O23: 0.0053870465
A24: DSB1_Chr15_L15 | B24: 1.7436546 | C24: DSB1_Chr15_L15 | D24: 1.0094299 | E24: Chr15_L15 | F24: 9.1704623 | G24: Chr15_L15 | H24: 1.5109261 | K24: DSB1_Chr15_L15 | L24: 9.1704623 | M24: 1.5109261 | N24: 1.7436546 | O24: 1.0094299
A25: DSB1_Chr15_L17_2 | B25: 2.2713598 | C25: DSB1_Chr15_L17_2 | D25: 1.0463696 | G25: Chr15_L17_2 | H25: 2.9580014 | K25: DSB1_Chr15_L17_2 | M25: 2.9580014 | N25: 2.2713598 | O25: 1.0463696
A26: DSB1_Chr15_L18 | B26: 0.32363868 | C26: DSB1_Chr15_L18 | D26: 0.13005869 | E26: Chr15_L18 | F26: 0.90482948 | G26: Chr15_L18 | H26: 0.49171349 | K26: DSB1_Chr15_L18 | L26: 0.90482948 | M26: 0.49171349 | N26: 0.32363868 | O26: 0.13005869
A27: DSB1_UNCUTTABLE | B27: 3.3295866 | C27: DSB1_UNCUTTABLE | D27: 4.5171667 | G27: DSB1_UNCUTTABLE | H27: 2.9410998 | K27: DSB1_UNCUTTABLE | M27: 2.9410998 | N27: 3.3295866 | O27: 4.5171667
A28: DSB2_UNCUTTABLE | B28: 0.65828722 | C28: DSB2_UNCUTTABLE | D28: 1.2662124 | E28: NO_CUT | F28: 0.0074779296 | G28: DSB2_UNCUTTABLE | H28: 0.92427112 | K28: DSB2_UNCUTTABLE | L28: 0.0074779296 | M28: 0.92427112 | N28: 0.65828722 | O28: 1.2662124
G33: LIGATED_A_to_C | H33: 0.012624089
G34: LIGATED_B_to_D | H34: 0.013771734

Sheet T120 aggregated CIS
A3: Time 360 | C3: T120 | N3: Batch 3 | O3: Batch 4 | P3: Batch 6 | Q3: Batch 8
A4: Freq | B4: Strain | C4: Strain | D4: Freq | E4: Strain | G4: T120 | H4: Strain | J4: T120 | M4: Strain | N4: Chr III | O4: Chr VII | P4: Chr IV | Q4: Chr XV
A5: 5.7883131 | B5: DSB2_Chr3 | C5: DSB2_Chr7 | D5: 44.850027 | E5: DSB2_Chr4 | G5: 17.597341 | H5: DSB2_Chr15 | J5: 1.0835659 | M5: DSB2_Locus | N5: 5.7883131 | O5: 44.850027 | P5: 17.597341 | Q5: 1.0835659
A6: 18.731883 | B6: Chr3_L02 | C6: Chr3_L02 | D6: 3.3803378 | E6: DSB1_Chr3_L02 | G6: 1.6148648 | H6: DSB1_Chr3_L02 | J6: 5.0086706 | M6: DSB1_Chr3_L02 | N6: 18.731883 | O6: 3.3803378 | P6: 1.6148648 | Q6: 5.0086706
A7: 0.011066477 | B7: Chr3_L03 | E7: DSB1_Chr3_L03 | G7: 1.0881839 | H7: DSB1_Chr3_L03 | J7: 0.082857905 | M7: DSB1_Chr3_L03 | N7: 0.011066477 | P7: 1.0881839 | Q7: 0.082857905
C8: Chr3_L04 | D8: 5.5811701 | E8: DSB1_Chr3_L04 | G8: 13.365202 | H8: DSB1_Chr3_L04 | J8: 0.16494623 | M8: DSB1_Chr3_L04 | O8: 5.5811701 | P8: 13.365202 | Q8: 0.16494623
A9: 7.9494324 | B9: Chr4_L01 | C9: Chr4_L01 | D9: 1.4231354 | E9: DSB1_Chr4_L01 | G9: 0.90818545 | H9: DSB1_Chr4_L01 | J9: 1.5773785 | M9: DSB1_Chr4_L01 | N9: 7.9494324 | O9: 1.4231354 | P9: 0.90818545 | Q9: 1.5773785
A10: 9.7750505 | B10: Chr4_L03 | C10: Chr4_L03 | D10: 1.7802767 | E10: DSB1_Chr4_L03 | G10: 0.39865936 | H10: DSB1_Chr4_L03 | J10: 2.5396076 | M10: DSB1_Chr4_L03 | N10: 9.7750505 | O10: 1.7802767 | P10: 0.39865936 | Q10: 2.5396076
A11: 7.1331628 | B11: Chr4_L06_2 | C11: Chr4_L06_2 | D11: 1.5718022 | E11: DSB1_Chr4_L06_2 | G11: 1.0275016 | H11: DSB1_Chr4_L06_2 | J11: 1.7433508 | M11: DSB1_Chr4_L06_2 | N11: 7.1331628 | O11: 1.5718022 | P11: 1.0275016 | Q11: 1.7433508
A12: 8.3534758 | B12: Chr4_L10_2 | C12: Chr4_L10_2 | D12: 4.1771779 | E12: DSB1_Chr4_L10_2 | G12: 1.6773394 | H12: DSB1_Chr4_L10_2 | J12: 1.7956822 | M12: DSB1_Chr4_L10_2 | N12: 8.3534758 | O12: 4.1771779 | P12: 1.6773394 | Q12: 1.7956822
A13: 9.6655937 | B13: Chr4_L12_2 | C13: Chr4_L12_2 | D13: 2.5741838 | E13: DSB1_Chr4_L12_2 | G13: 1.8491444 | H13: DSB1_Chr4_L12_2 | J13: 2.5478165 | M13: DSB1_Chr4_L12_2 | N13: 9.6655937 | O13: 2.5741838 | P13: 1.8491444 | Q13: 2.5478165
C14: Chr4_L13 | D14: 1.1252864 | E14: DSB1_Chr4_L13 | G14: 0.66545644 | H14: DSB1_Chr4_L13 | J14: 0.043096372 | M14: DSB1_Chr4_L13 | O14: 1.1252864 | P14: 0.66545644 | Q14: 0.043096372
A15: 3.7922557 | B15: Chr4_L15_2 | C15: Chr4_L15_2 | D15: 1.9929919 | E15: DSB1_Chr4_L15_2 | G15: 1.5608397 | H15: DSB1_Chr4_L15_2 | J15: 1.1895112 | M15: DSB1_Chr4_L15_2 | N15: 3.7922557 | O15: 1.9929919 | P15: 1.5608397 | Q15: 1.1895112
A16: 2.06043 | B16: Chr7_990K | C16: Chr7_990K | D16: 0.69371259 | E16: DSB1_Chr7_990K | G16: 1.4783938 | H16: DSB1_Chr7_990K | J16: 0.32296626 | M16: DSB1_Chr7_990K | N16: 2.06043 | O16: 0.69371259 | P16: 1.4783938 | Q16: 0.32296626
C17: Chr7_L03 | D17: 1.7983497 | E17: DSB1_Chr7_L03 | G17: 0.43092081 | H17: DSB1_Chr7_L03 | J17: 0.025652602 | M17: DSB1_Chr7_L03 | O17: 1.7983497 | P17: 0.43092081 | Q17: 0.025652602
A18: 0.18528556 | B18: Chr7_L06 | C18: Chr7_L06 | D18: 3.0530013 | E18: DSB1_Chr7_L06 | G18: 1.2809844 | H18: DSB1_Chr7_L06 | J18: 0.14647636 | M18: DSB1_Chr7_L06 | N18: 0.18528556 | O18: 3.0530013 | P18: 1.2809844 | Q18: 0.14647636
C19: Chr7_L09 | D19: 1.5074763 | E19: DSB1_Chr7_L09 | G19: 0.54383589 | H19: DSB1_Chr7_L09 | J19: 0.044122476 | M19: DSB1_Chr7_L09 | O19: 1.5074763 | P19: 0.54383589 | Q19: 0.044122476
A20: 1.1135448 | B20: Chr12_L01 | C20: Chr12_L01 | D20: 1.1226706 | E20: DSB1_Chr12_L01 | G20: 0.90844149 | H20: DSB1_Chr12_L01 | J20: 0.24959982 | M20: DSB1_Chr12_L01 | N20: 1.1135448 | O20: 1.1226706 | P20: 0.90844149 | Q20: 0.24959982
A21: 5.5657366 | B21: Chr12_L05 | C21: Chr12_L05 | D21: 1.2307919 | E21: DSB1_Chr12_L05 | G21: 3.7561546 | H21: DSB1_Chr12_L05 | J21: 1.6189357 | M21: DSB1_Chr12_L05 | N21: 5.5657366 | O21: 1.2307919 | P21: 3.7561546 | Q21: 1.6189357
A22: 0.74215537 | B22: Chr12_L07 | C22: Chr12_L07 | D22: 1.6894357 | E22: DSB1_Chr12_L07 | G22: 1.0129071 | H22: DSB1_Chr12_L07 | J22: 0.16494623 | M22: DSB1_Chr12_L07 | N22: 0.74215537 | O22: 1.6894357 | P22: 1.0129071 | Q22: 0.16494623
A23: 0.75739126 | B23: Chr12_L12 | C23: Chr12_L12 | D23: 2.1550154 | E23: DSB1_Chr12_L12 | G23: 0.668785 | H23: DSB1_Chr12_L12 | J23: 0.24908677 | M23: DSB1_Chr12_L12 | N23: 0.75739126 | O23: 2.1550154 | P23: 0.668785 | Q23: 0.24908677
A24: 7.2641291 | B24: Chr15_L01 | C24: Chr15_L01 | D24: 2.0848237 | E24: DSB1_Chr15_L01 | G24: 1.8340379 | H24: DSB1_Chr15_L01 | J24: 1.9726851 | M24: DSB1_Chr15_L01 | N24: 7.2641291 | O24: 2.0848237 | P24: 1.8340379 | Q24: 1.9726851
A25: 0.004987708 | B25: Chr15_L04 | E25: DSB1_Chr15_L04 | G25: 0.0087054709 | H25: DSB1_Chr15_L04 | J25: 0.0051305204 | M25: DSB1_Chr15_L04 | N25: 0.004987708 | P25: 0.0087054709 | Q25: 0.0051305204
A26: 10.567745 | B26: Chr15_L15 | C26: Chr15_L15 | D26: 1.2028104 | E26: DSB1_Chr15_L15 | G26: 0.75942431 | H26: DSB1_Chr15_L15 | J26: 1.8333915 | M26: DSB1_Chr15_L15 | N26: 10.567745 | O26: 1.2028104 | P26: 0.75942431 | Q26: 1.8333915
C27: Chr15_L17_2 | D27: 2.1802226 | E27: DSB1_Chr15_L17_2 | G27: 1.1383683 | H27: DSB1_Chr15_L17_2 | J27: 0.050792152 | M27: DSB1_Chr15_L17_2 | O27: 2.1802226 | P27: 1.1383683 | Q27: 0.050792152
A28: 0.52994398 | B28: Chr15_L18 | C28: Chr15_L18 | D28: 0.42868054 | E28: DSB1_Chr15_L18 | G28: 0.14492049 | H28: DSB1_Chr15_L18 | J28: 0.11261492 | M28: DSB1_Chr15_L18 | N28: 0.52994398 | O28: 0.42868054 | P28: 0.14492049 | Q28: 0.11261492
C29: DSB1_UNCUTTABLE | D29: 10.110059 | E29: DSB1_UNCUTTABLE | G29: 5.2611769 | H29: DSB1_UNCUTTABLE | J29: 3.0777992 | M29: DSB1_UNCUTTABLE | O29: 10.110059 | P29: 5.2611769 | Q29: 3.0777992
A30: 0.0084167573 | B30: NO_CUT | C30: DSB2_UNCUTTABLE | D30: 2.2865604 | E30: DSB2_UNCUTTABLE | G30: 0.59530058 | H30: DSB2_UNCUTTABLE | J30: 20.466929 | M30: DSB2_UNCUTTABLE | N30: 0.0084167573 | O30: 2.2865604 | P30: 0.59530058 | Q30: 20.466929
C35: LIGATED_A_to_C | D35: 0.070310583
C36: LIGATED_B_to_D | D36: 0.030002881
N39: 0.0084167573
N40: 5.7883131

Sheet CIS Fold Change
B1: Batch 3 | C1: Batch 4 | D1: Batch 6 | E1: Batch 8
A2: Strain | B2: Chr III | C2: Chr VII | D2: Chr IV | E2: Chr XV
A3: DSB2_Locus | B3: ='T120 aggregated CIS'!N5/'T0 aggregated CIS'!L3 -> 0.82759554 | C3: ='T120 aggregated CIS'!O5/'T0 aggregated CIS'!M3 -> 0.95540103 | D3: ='T120 aggregated CIS'!P5/'T0 aggregated CIS'!N3 -> 0.41703377 | E3: ='T120 aggregated CIS'!Q5/'T0 aggregated CIS'!O3 -> 0.019768155
A4: DSB1_Chr3_L02 | B4: ='T120 aggregated CIS'!N6/'T0 aggregated CIS'!L4 -> 1.2174987 | C4: ='T120 aggregated CIS'!O6/'T0 aggregated CIS'!M4 -> 1.215533 | D4: ='T120 aggregated CIS'!P6/'T0 aggregated CIS'!N4 -> 0.48515385 | E4: ='T120 aggregated CIS'!Q6/'T0 aggregated CIS'!O4 -> 1.7465784
A5: DSB1_Chr3_L03 | B5: ='T120 aggregated CIS'!N7/'T0 aggregated CIS'!L5 -> 1.155349 | C5: ='T120 aggregated CIS'!O7/'T0 aggregated CIS'!M5 -> 0 | D5: ='T120 aggregated CIS'!P7/'T0 aggregated CIS'!N5 -> 0.78254465 | E5: ='T120 aggregated CIS'!Q7/'T0 aggregated CIS'!O5 -> 0.046468134
A6: DSB1_Chr3_L04 | B6: ='T120 aggregated CIS'!N8/'T0 aggregated CIS'!L6 -> #DIV/0! | C6: ='T120 aggregated CIS'!O8/'T0 aggregated CIS'!M6 -> #DIV/0! | D6: ='T120 aggregated CIS'!P8/'T0 aggregated CIS'!N6 -> 0.98297648 | E6: ='T120 aggregated CIS'!Q8/'T0 aggregated CIS'!O6 -> 0.035660806
A7: DSB1_Chr4_L01 | B7: ='T120 aggregated CIS'!N9/'T0 aggregated CIS'!L7 -> 1.020028 | C7: ='T120 aggregated CIS'!O9/'T0 aggregated CIS'!M7 -> 0.84242459 | D7: ='T120 aggregated CIS'!P9/'T0 aggregated CIS'!N7 -> 0.46263206 | E7: ='T120 aggregated CIS'!Q9/'T0 aggregated CIS'!O7 -> 1.0205809 | AA7: relate this back to uncuttable
A8: DSB1_Chr4_L03 | B8: ='T120 aggregated CIS'!N10/'T0 aggregated CIS'!L8 -> 1.1491014 | C8: ='T120 aggregated CIS'!O10/'T0 aggregated CIS'!M8 -> 0.87907293 | D8: ='T120 aggregated CIS'!P10/'T0 aggregated CIS'!N8 -> 0.19186691 | E8: ='T120 aggregated CIS'!Q10/'T0 aggregated CIS'!O8 -> 0.85117359 | AA8: what are all the outcomes for each allele
A9: DSB1_Chr4_L06_2 | B9: ='T120 aggregated CIS'!N11/'T0 aggregated CIS'!L9 -> 0.91670204 | C9: ='T120 aggregated CIS'!O11/'T0 aggregated CIS'!M9 -> 0.81895458 | D9: ='T120 aggregated CIS'!P11/'T0 aggregated CIS'!N9 -> 0.52962914 | E9: ='T120 aggregated CIS'!Q11/'T0 aggregated CIS'!O9 -> 1.2340657 | AA9: CIS to trans ratio
A10: DSB1_Chr4_L10_2 | B10: ='T120 aggregated CIS'!N12/'T0 aggregated CIS'!L10 -> 1.2380668 | C10: ='T120 aggregated CIS'!O12/'T0 aggregated CIS'!M10 -> 0.88543553 | D10: ='T120 aggregated CIS'!P12/'T0 aggregated CIS'!N10 -> 0.86356446 | E10: ='T120 aggregated CIS'!Q12/'T0 aggregated CIS'!O10 -> 0.9754738
A11: DSB1_Chr4_L12_2 | B11: ='T120 aggregated CIS'!N13/'T0 aggregated CIS'!L11 -> 1.1237804 | C11: ='T120 aggregated CIS'!O13/'T0 aggregated CIS'!M11 -> 1.0919263 | D11: ='T120 aggregated CIS'!P13/'T0 aggregated CIS'!N11 -> 0.79995569 | E11: ='T120 aggregated CIS'!Q13/'T0 aggregated CIS'!O11 -> 1.6879674
A12: DSB1_Chr4_L13 | B12: ='T120 aggregated CIS'!N14/'T0 aggregated CIS'!L12 -> #DIV/0! | C12: ='T120 aggregated CIS'!O14/'T0 aggregated CIS'!M12 -> 0.54719199 | D12: ='T120 aggregated CIS'!P14/'T0 aggregated CIS'!N12 -> 0.54554996 | E12: ='T120 aggregated CIS'!Q14/'T0 aggregated CIS'!O12 -> 0.032079435
A13: DSB1_Chr4_L15_2 | B13: ='T120 aggregated CIS'!N15/'T0 aggregated CIS'!L13 -> 0.76400318 | C13: ='T120 aggregated CIS'!O15/'T0 aggregated CIS'!M13 -> 0.8816823 | D13: ='T120 aggregated CIS'!P15/'T0 aggregated CIS'!N13 -> 0.82893663 | E13: ='T120 aggregated CIS'!Q15/'T0 aggregated CIS'!O13 -> 1.1665409
A14: DSB1_Chr7_990K | B14: ='T120 aggregated CIS'!N16/'T0 aggregated CIS'!L14 -> 0.79500094 | C14: ='T120 aggregated CIS'!O16/'T0 aggregated CIS'!M14 -> 0.43184589 | D14: ='T120 aggregated CIS'!P16/'T0 aggregated CIS'!N14 -> 0.72483053 | E14: ='T120 aggregated CIS'!Q16/'T0 aggregated CIS'!O14 -> 0.31585549
A15: DSB1_Chr7_L03 | B15: ='T120 aggregated CIS'!N17/'T0 aggregated CIS'!L15 -> #DIV/0! | C15: ='T120 aggregated CIS'!O17/'T0 aggregated CIS'!M15 -> 0.69196758 | D15: ='T120 aggregated CIS'!P17/'T0 aggregated CIS'!N15 -> 0.42878981 | E15: ='T120 aggregated CIS'!Q17/'T0 aggregated CIS'!O15 -> 0.015745552
A16: DSB1_Chr7_L06 | B16: ='T120 aggregated CIS'!N18/'T0 aggregated CIS'!L16 -> 0.98140245 | C16: ='T120 aggregated CIS'!O18/'T0 aggregated CIS'!M16 -> 1.0675091 | D16: ='T120 aggregated CIS'!P18/'T0 aggregated CIS'!N16 -> 0.85302643 | E16: ='T120 aggregated CIS'!Q18/'T0 aggregated CIS'!O16 -> 0.05727756
A17: DSB1_Chr7_L09 | B17: ='T120 aggregated CIS'!N19/'T0 aggregated CIS'!L17 -> #DIV/0! | C17: ='T120 aggregated CIS'!O19/'T0 aggregated CIS'!M17 -> 0.74180792 | D17: ='T120 aggregated CIS'!P19/'T0 aggregated CIS'!N17 -> 0.27279733 | E17: ='T120 aggregated CIS'!Q19/'T0 aggregated CIS'!O17 -> 0.024130191
A18: DSB1_Chr12_L01 | B18: ='T120 aggregated CIS'!N20/'T0 aggregated CIS'!L18 -> 0.78620542 | C18: ='T120 aggregated CIS'!O20/'T0 aggregated CIS'!M18 -> 0.45993456 | D18: ='T120 aggregated CIS'!P20/'T0 aggregated CIS'!N18 -> 0.49107266 | E18: ='T120 aggregated CIS'!Q20/'T0 aggregated CIS'!O18 -> 0.13598882
A19: DSB1_Chr12_L05 | B19: ='T120 aggregated CIS'!N21/'T0 aggregated CIS'!L19 -> 0.6767019 | C19: ='T120 aggregated CIS'!O21/'T0 aggregated CIS'!M19 -> 0.78078998 | D19: ='T120 aggregated CIS'!P21/'T0 aggregated CIS'!N19 -> 0.89287888 | E19: ='T120 aggregated CIS'!Q21/'T0 aggregated CIS'!O19 -> 2.10507
A20: DSB1_Chr12_L07 | B20: ='T120 aggregated CIS'!N22/'T0 aggregated CIS'!L20 -> 0.69169171 | C20: ='T120 aggregated CIS'!O22/'T0 aggregated CIS'!M20 -> 0.83186005 | D20: ='T120 aggregated CIS'!P22/'T0 aggregated CIS'!N20 -> 0.62863499 | E20: ='T120 aggregated CIS'!Q22/'T0 aggregated CIS'!O20 -> 0.13055838
A21: DSB1_Chr12_L12 | B21: ='T120 aggregated CIS'!N23/'T0 aggregated CIS'!L21 -> 0.60796088 | C21: ='T120 aggregated CIS'!O23/'T0 aggregated CIS'!M21 -> 0.90685777 | D21: ='T120 aggregated CIS'!P23/'T0 aggregated CIS'!N21 -> 0.43913921 | E21: ='T120 aggregated CIS'!Q23/'T0 aggregated CIS'!O21 -> 0.101718
... A28: DSB2_UNCUTTABLE | B28: ='T120 aggregated CIS'!N30/'T0 aggregated CIS'!L28 -> 1.1255465 | C28: ='T120 aggregated CIS'!O30/'T0 aggregated CIS'!M28 -> 2.4739066 | D28: ='T120 aggregated CIS'!P30/'T0 aggregated CIS'!N28 -> 0.90431739 | E28: ='T120 aggregated CIS'!Q30/'T0 aggregated CIS'!O28 -> 16.163898
D32: 2 fold or greater increase
D33: 2 fold or greater decrease

Sheet T0 aggregated TRANS
C1: Chr III | E1: Batch 4 | G1: Batch 6 | I1: Batch 8
D2: T0 | E2: Strain | F2: T0 | G2: Strain | H2: T0 | I2: Strain | J2: T0 | M2: Strain | N2: ChrIII | O2: Chr VII | P2: Chr IV | Q2: Chr XV
C3: TRANS_A_to_D_Chr3_L02 | D3: 18 | E3: TRANS_A_to_D_Chr3_L02 | F3: 6.6098081 | G3: TRANS_A_to_D_Chr3_L02 | H3: 9.2937827 | I3: TRANS_A_to_D_Chr3_L02 | J3: 8.8852529 | M3: TRANS_A_to_D_Chr3_L02 | N3: 18 | O3: 6.6098081 | P3: 9.2937827 | Q3: 8.8852529
C4: TRANS_A_to_D_Chr3_L03 | D4: 0.4 | E4: TRANS_A_to_D_Chr3_L04 | F4: 4.3976546 | G4: TRANS_A_to_D_Chr3_L03 | H4: 1.9101846 | I4: TRANS_A_to_D_Chr3_L03 | J4: 2.070143 | M4: TRANS_A_to_D_Chr3_L03 | N4: 0.4 | O4: 4.3976546 | P4: 1.9101846 | Q4: 2.070143
C5: TRANS_A_to_D_Chr4_L01 | D5: 6.7 | E5: TRANS_A_to_D_Chr4_L01 | F5: 3.1716418 | G5: TRANS_A_to_D_Chr3_L04 | H5: 24.125264 | I5: TRANS_A_to_D_Chr3_L04 | J5: 11.595646 | M5: TRANS_A_to_D_Chr3_L04 | N5: 6.7 | O5: 3.1716418 | P5: 24.125264 | Q5: 11.595646
C6: TRANS_A_to_D_Chr4_L03 | D6: 12.5 | E6: TRANS_A_to_D_Chr4_L03 | F6: 17.510661 | G6: TRANS_A_to_D_Chr4_L01 | H6: 4.2244467 | I6: TRANS_A_to_D_Chr4_L01 | J6: 1.3729814 | M6: TRANS_A_to_D_Chr4_L01 | N6: 12.5 | O6: 17.510661 | P6: 4.2244467 | Q6: 1.3729814
C7: TRANS_A_to_D_Chr4_L06_2 | D7: 12.4 | E7: TRANS_A_to_D_Chr4_L06_2 | F7: 2.3454158 | G7: TRANS_A_to_D_Chr4_L03 | H7: 2.7734411 | I7: TRANS_A_to_D_Chr4_L03 | J7: 2.4116099 | M7: TRANS_A_to_D_Chr4_L03 | N7: 12.4 | O7: 2.3454158 | P7: 2.7734411 | Q7: 2.4116099
C8: TRANS_A_to_D_Chr4_L10_2 | D8: 4.5 | E8: TRANS_A_to_D_Chr4_L10_2 | F8: 8.4754797 | G8: TRANS_A_to_D_Chr4_L06_2 | H8: 5.1979061 | I8: TRANS_A_to_D_Chr4_L06_2 | J8: 1.9563207 | M8: TRANS_A_to_D_Chr4_L06_2 | N8: 4.5 | O8: 8.4754797 | P8: 5.1979061 | Q8: 1.9563207
C9: TRANS_A_to_D_Chr4_L12_2 | D9: 4.8 | E9: TRANS_A_to_D_Chr4_L12_2 | F9: 10.287846 | G9: TRANS_A_to_D_Chr4_L10_2 | H9: 1.267334 | I9: TRANS_A_to_D_Chr4_L10_2 | J9: 1.7144483 | M9: TRANS_A_to_D_Chr4_L10_2 | N9: 4.8 | O9: 10.287846 | P9: 1.267334 | Q9: 1.7144483
C10: TRANS_A_to_D_Chr4_L15_2 | D10: 2.9 | E10: TRANS_A_to_D_Chr4_L13 | F10: 1.4925373 | G10: TRANS_A_to_D_Chr4_L12_2 | H10: 0.84488934 | I10: TRANS_A_to_D_Chr4_L12_2 | J10: 1.73579 | M10: TRANS_A_to_D_Chr4_L12_2 | N10: 2.9 | O10: 1.4925373 | P10: 0.84488934 | Q10: 1.73579
C11: TRANS_A_to_D_Chr7_990K | D11: 1.5 | E11: TRANS_A_to_D_Chr4_L15_2 | F11: 1.945629 | G11: TRANS_A_to_D_Chr4_L13 | H11: 3.912205 | I11: TRANS_A_to_D_Chr4_L13 | J11: 5.9898983 | M11: TRANS_A_to_D_Chr4_L13 | N11: 1.5 | O11: 1.945629 | P11: 3.912205 | Q11: 5.9898983
C12: TRANS_A_to_D_Chr7_L06 | D12: 0.2 | E12: TRANS_A_to_D_Chr7_990K | F12: 0.93283582 | G12: TRANS_A_to_D_Chr4_L15_2 | H12: 2.4428322 | I12: TRANS_A_to_D_Chr4_L15_2 | J12: 1.3516398 | M12: TRANS_A_to_D_Chr4_L15_2 | N12: 0.2 | O12: 0.93283582 | P12: 2.4428322 | Q12: 1.3516398
C13: TRANS_A_to_D_NO_CUT | D13: 0.3 | E13: TRANS_A_to_D_Chr7_L03 | F13: 3.5447761 | G13: TRANS_A_to_D_Chr7_990K | H13: 2.7734411 | I13: TRANS_A_to_D_Chr7_990K | J13: 0.6544782 | M13: TRANS_A_to_D_Chr7_990K | N13: 0.3 | O13: 3.5447761 | P13: 2.7734411 | Q13: 0.6544782
E14: TRANS_A_to_D_Chr7_L06 | F14: 2.4520256 | G14: TRANS_A_to_D_Chr7_L03 | H14: 2.8744605 | I14: TRANS_A_to_D_Chr7_L03 | J14: 4.2469944 | M14: TRANS_A_to_D_Chr7_L03 | O14: 2.4520256 | P14: 2.8744605 | Q14: 4.2469944
E15: TRANS_A_to_D_Chr7_L09 | F15: 0.93283582 | G15: TRANS_A_to_D_Chr7_L06 | H15: 0.98264303 | I15: TRANS_A_to_D_Chr7_L06 | J15: 1.7073344 | M15: TRANS_A_to_D_Chr7_L06 | O15: 0.93283582 | P15: 0.98264303 | Q15: 1.7073344
G16: TRANS_A_to_D_Chr7_L09 | H16: 5.2897419 | I16: TRANS_A_to_D_Chr7_L09 | J16: 4.8445614 | M16: TRANS_A_to_D_Chr7_L09 | P16: 5.2897419 | Q16: 4.8445614
C17: TRANS_A_to_D_Chr12_L01 | D17: 1.6 | E17: TRANS_A_to_D_Chr12_L01 | F17: 3.4381663 | G17: TRANS_A_to_D_Chr12_L01 | H17: 2.7642575 | I17: TRANS_A_to_D_Chr12_L01 | J17: 1.1026535 | M17: TRANS_A_to_D_Chr12_L01 | N17: 1.6 | O17: 3.4381663 | P17: 2.7642575 | Q17: 1.1026535
C18: TRANS_A_to_D_Chr12_L05 | D18: 5.6 | E18: TRANS_A_to_D_Chr12_L05 | F18: 2.6119403 | G18: TRANS_A_to_D_Chr12_L05 | H18: 2.1765084 | I18: TRANS_A_to_D_Chr12_L05 | J18: 1.2591591 | M18: TRANS_A_to_D_Chr12_L05 | N18: 5.6 | O18: 2.6119403 | P18: 2.1765084 | Q18: 1.2591591
C19: TRANS_A_to_D_Chr12_L07 | D19: 1.6 | E19: TRANS_A_to_D_Chr12_L07 | F19: 1.7590618 | G19: TRANS_A_to_D_Chr12_L07 | H19: 3.2601708 | I19: TRANS_A_to_D_Chr12_L07 | J19: 4.2327666 | M19: TRANS_A_to_D_Chr12_L07 | N19: 1.6 | O19: 1.7590618 | P19: 3.2601708 | Q19: 4.2327666
C20: TRANS_A_to_D_Chr12_L12 | D20: 2.2 | E20: TRANS_A_to_D_Chr12_L12 | F20: 2.2654584 | G20: TRANS_A_to_D_Chr12_L12 | H20: 7.5305354 | I20: TRANS_A_to_D_Chr12_L12 | J20: 24.621185 | M20: TRANS_A_to_D_Chr12_L12 | N20: 2.2 | O20: 2.2654584 | P20: 7.5305354 | Q20: 24.621185
C21: TRANS_A_to_D_Chr15_L01 | D21: 8.5 | E21: TRANS_A_to_D_Chr15_L01 | F21: 1.652452 | G21: TRANS_A_to_D_Chr15_L01 | H21: 2.5254844 | I21: TRANS_A_to_D_Chr15_L01 | J21: 4.7236252 | M21: TRANS_A_to_D_Chr15_L01 | N21: 8.5 | O21: 1.652452 | P21: 2.5254844 | Q21: 4.7236252
C22: TRANS_A_to_D_Chr15_L04 | D22: 0.3 | E22: TRANS_A_to_D_Chr15_L04 | F22: 0.053304904 | G22: TRANS_A_to_D_Chr15_L04 | H22: 0.045917899 | I22: TRANS_A_to_D_Chr15_L04 | J22: 0.014227787 | M22: TRANS_A_to_D_Chr15_L04 | N22: 0.3 | O22: 0.053304904 | P22: 0.045917899 | Q22: 0.014227787
C23: TRANS_A_to_D_Chr15_L15 | D23: 9.3 | E23: TRANS_A_to_D_Chr15_L15 | F23: 0.6663113 | G23: TRANS_A_to_D_Chr15_L15 | H23: 3.9581229 | I23: TRANS_A_to_D_Chr15_L15 | J23: 1.6290816 | M23: TRANS_A_to_D_Chr15_L15 | N23: 9.3 | O23: 0.6663113 | P23: 3.9581229 | Q23: 1.6290816
C24: TRANS_A_to_D_Chr15_L18 | D24: 6.6 | E24: TRANS_A_to_D_Chr15_L17_2 | F24: 1.4658849 | G24: TRANS_A_to_D_Chr15_L17_2 | H24: 5.1519882 | I24: TRANS_A_to_D_Chr15_L17_2 | J24: 1.4939176 | M24: TRANS_A_to_D_Chr15_L17_2 | N24: 6.6 | O24: 1.4658849 | P24: 5.1519882 | Q24: 1.4939176
E25: TRANS_A_to_D_Chr15_L18 | F25: 1.8656716 | G25: TRANS_A_to_D_Chr15_L18 | H25: 0.34897603 | I25: TRANS_A_to_D_Chr15_L18 | J25: 0.0071138934 | M25: TRANS_A_to_D_Chr15_L18 | O25: 1.8656716 | P25: 0.34897603 | Q25: 0.0071138934
E26: TRANS_A_to_D_UNCUTTABLE | F26: 1.7324094 | G26: TRANS_A_to_D_UNCUTTABLE | H26: 4.3254661 | I26: TRANS_A_to_D_UNCUTTABLE | J26: 10.379171 | M26: TRANS_A_to_D_UNCUTTABLE | O26: 1.7324094 | P26: 4.3254661 | Q26: 10.379171
C27: TRANS_C_to_B_Chr3_L02 | D27: 5.3 | E27: TRANS_C_to_B_Chr3_L02 | F27: 0.26652452 | G27: TRANS_C_to_B_Chr3_L02 | H27: 5.6939502 | I27: TRANS_C_to_B_Chr3_L02 | J27: 11.353712 | M27: TRANS_C_to_B_Chr3_L02 | N27: 5.3 | O27: 0.26652452 | P27: 5.6939502 | Q27: 11.353712
C28: TRANS_C_to_B_Chr3_L03 | D28: 0 | E28: TRANS_C_to_B_Chr3_L03 | G28: TRANS_C_to_B_Chr3_L03 | H28: 2.4911032 | I28: TRANS_C_to_B_Chr3_L03 | J28: 1.0917031 | M28: TRANS_C_to_B_Chr3_L03 | N28: 0 | P28: 2.4911032 | Q28: 1.0917031
E29: TRANS_C_to_B_Chr3_L04 | F29: 1.0927505 | G29: TRANS_C_to_B_Chr3_L04 | H29: 12.811388 | I29: TRANS_C_to_B_Chr3_L04 | J29: 2.6200873 | M29: TRANS_C_to_B_Chr3_L04 | O29: 1.0927505 | P29: 12.811388 | Q29: 2.6200873
C30: TRANS_C_to_B_Chr3_L18 | D30: 0.1 | E30: TRANS_C_to_B_Chr3_L18 | F30: 0.079957356 | G30: TRANS_C_to_B_Chr3_L18 | I30: TRANS_C_to_B_Chr3_L18 | M30: TRANS_C_to_B_Chr3_L18 | N30: 0.1 | O30: 0.079957356
C31: TRANS_C_to_B_Chr4_L01 | D31: 1.6 | E31: TRANS_C_to_B_Chr4_L01 | F31: 0.47974414 | G31: TRANS_C_to_B_Chr4_L01 | H31: 2.1352313 | I31: TRANS_C_to_B_Chr4_L01 | J31: 3.0567686 | M31: TRANS_C_to_B_Chr4_L01 | N31: 1.6 | O31: 0.47974414 | P31: 2.1352313 | Q31: 3.0567686
C32: TRANS_C_to_B_Chr4_L03 | D32: 2.6 | E32: TRANS_C_to_B_Chr4_L03 | F32: 0.45309168 | G32: TRANS_C_to_B_Chr4_L03 | H32: 5.6939502 | I32: TRANS_C_to_B_Chr4_L03 | J32: 6.1135371 | M32: TRANS_C_to_B_Chr4_L03 | N32: 2.6 | O32: 0.45309168 | P32: 5.6939502 | Q32: 6.1135371
C33: TRANS_C_to_B_Chr4_L06_2 | D33: 5.5 | E33: TRANS_C_to_B_Chr4_L06_2 | F33: 2.3987207 | G33: TRANS_C_to_B_Chr4_L06_2 | H33: 1.7793594 | I33: TRANS_C_to_B_Chr4_L06_2 | J33: 1.0917031 | M33: TRANS_C_to_B_Chr4_L06_2 | N33: 5.5 | O33: 2.3987207 | P33: 1.7793594 | Q33: 1.0917031 | U33: make a correlation plot for AB, CD
C34: TRANS_C_to_B_Chr4_L10_2 | D34: 1.4 | E34: TRANS_C_to_B_Chr4_L10_2 | F34: 0.58635394 | G34: TRANS_C_to_B_Chr4_L10_2 | H34: 2.8469751 | I34: TRANS_C_to_B_Chr4_L10_2 | J34: 5.8951965 | M34: TRANS_C_to_B_Chr4_L10_2 | N34: 1.4 | O34: 0.58635394 | P34: 2.8469751 | Q34: 5.8951965
C35: TRANS_C_to_B_Chr4_L12_2 | D35: 0.5 | E35: TRANS_C_to_B_Chr4_L12_2 | F35: 2.3187633 | G35: TRANS_C_to_B_Chr4_L12_2 | H35: 6.7615658 | I35: TRANS_C_to_B_Chr4_L12_2 | J35: 1.0917031 | M35: TRANS_C_to_B_Chr4_L12_2 | N35: 0.5 | O35: 2.3187633 | P35: 6.7615658 | Q35: 1.0917031
E36: TRANS_C_to_B_Chr4_L13 | F36: 0.23987207 | G36: TRANS_C_to_B_Chr4_L13 | H36: 0.71174377 | I36: TRANS_C_to_B_Chr4_L13 | J36: 0.43668122 | M36: TRANS_C_to_B_Chr4_L13 | O36: 0.23987207 | P36: 0.71174377 | Q36: 0.43668122
C37: TRANS_C_to_B_Chr4_L15_2 | D37: 0.3 | E37: TRANS_C_to_B_Chr4_L15_2 | F37: 0.21321962 | G37: TRANS_C_to_B_Chr4_L15_2 | H37: 14.234875 | I37: TRANS_C_to_B_Chr4_L15_2 | J37: 1.0917031 | M37: TRANS_C_to_B_Chr4_L15_2 | N37: 0.3 | O37: 0.21321962 | P37: 14.234875 | Q37: 1.0917031
C38: TRANS_C_to_B_Chr7_990K | D38: 0.3 | E38: TRANS_C_to_B_Chr7_990K | F38: 1.1727079 | G38: TRANS_C_to_B_Chr7_990K | H38: 3.5587189 | I38: TRANS_C_to_B_Chr7_990K | J38: 4.3668122 | M38: TRANS_C_to_B_Chr7_990K | N38: 0.3 | O38: 1.1727079 | P38: 3.5587189 | Q38: 4.3668122
E39: TRANS_C_to_B_Chr7_L03 | F39: 0.47974414 | G39: TRANS_C_to_B_Chr7_L03 | H39: 1.7793594 | I39: TRANS_C_to_B_Chr7_L03 | J39: 1.3100437 | M39: TRANS_C_to_B_Chr7_L03 | O39: 0.47974414 | P39: 1.7793594 | Q39: 1.3100437
C40: TRANS_C_to_B_Chr7_L06 | D40: 0 | E40: TRANS_C_to_B_Chr7_L06 | F40: 0.53304904 | G40: TRANS_C_to_B_Chr7_L06 | H40: 3.9145907 | I40: TRANS_C_to_B_Chr7_L06 | J40: 16.157205 | M40: TRANS_C_to_B_Chr7_L06 | N40: 0 | O40: 0.53304904 | P40: 3.9145907 | Q40: 16.157205
...

Sheet T120 aggregated TRANS
C1: Chr VII | E1: Chr IV | G1: Chr XV
E2: Strain | F2: T120 | G2: Strain | H2: T120 | J2: Strain | K2: Chr III | L2: Chr VII | M2: Chr IV | N2: Chr XV
A3: TRANS_A_to_D_Chr3_L02 | B3: 10.8 | C3: Chr3_L02 | D3: 1.1043637 | E3: TRANS_A_to_D_Chr3_L02 | F3: 1.1663146 | G3: TRANS_A_to_D_Chr3_L02 | H3: 7.8323967 | J3: TRANS_A_to_D_Chr3_L02 | K3: 10.8 | L3: 1.1043637 | M3: 1.1663146 | N3: 7.8323967
A4: TRANS_A_to_D_Chr3_L03 | B4: 0.2 | E4: TRANS_A_to_D_Chr3_L03 | F4: 6.731564 | G4: TRANS_A_to_D_Chr3_L03 | H4: 0.042683361 | J4: TRANS_A_to_D_Chr3_L03 | K4: 0.2 | M4: 6.731564 | N4: 0.042683361
C5: Chr3_L04 | D5: 4.4830345 | E5: TRANS_A_to_D_Chr3_L04 | F5: 33.318027 | G5: TRANS_A_to_D_Chr3_L04 | H5: 0.2134168 | J5: TRANS_A_to_D_Chr3_L04 | L5: 4.4830345 | M5: 33.318027 | N5: 0.2134168
A6: TRANS_A_to_D_Chr4_L01 | B6: 3.5 | C6: Chr4_L01 | D6: 9.102475 | E6: TRANS_A_to_D_Chr4_L01 | F6: 0.50509689 | G6: TRANS_A_to_D_Chr4_L01 | H6: 1.9207512 | J6: TRANS_A_to_D_Chr4_L01 | K6: 3.5 | L6: 9.102475 | M6: 0.50509689 | N6: 1.9207512
A7: TRANS_A_to_D_Chr4_L03 | B7: 21.6 | C7: Chr4_L03 | D7: 1.5319439 | E7: TRANS_A_to_D_Chr4_L03 | F7: 0.44999541 | G7: TRANS_A_to_D_Chr4_L03 | H7: 5.9329871 | J7: TRANS_A_to_D_Chr4_L03 | K7: 21.6 | L7: 1.5319439 | M7: 0.44999541 | N7: 5.9329871
A8: TRANS_A_to_D_Chr4_L06_2 | B8: 11.7 | C8: Chr4_L06_2 | D8: 3.7629684 | E8: TRANS_A_to_D_Chr4_L06_2 | F8: 0.82652218 | G8: TRANS_A_to_D_Chr4_L06_2 | H8: 2.7175073 | J8: TRANS_A_to_D_Chr4_L06_2 | K8: 11.7 | L8: 3.7629684 | M8: 0.82652218 | N8: 2.7175073
A9: TRANS_A_to_D_Chr4_L10_2 | B9: 6.3 | C9: Chr4_L10_2 | D9: 2.566793 | E9: TRANS_A_to_D_Chr4_L10_2 | F9: 3.1958858 | G9: TRANS_A_to_D_Chr4_L10_2 | H9: 2.7103934 | J9: TRANS_A_to_D_Chr4_L10_2 | K9: 6.3 | L9: 2.566793 | M9: 3.1958858 | N9: 2.7103934
A10: TRANS_A_to_D_Chr4_L12_2 | B10: 3 | C10: Chr4_L12_2 | D10: 4.153824 | E10: TRANS_A_to_D_Chr4_L12_2 | F10: 8.4029755 | G10: TRANS_A_to_D_Chr4_L12_2 | H10: 1.3800953 | J10: TRANS_A_to_D_Chr4_L12_2 | K10: 3 | L10: 4.153824 | M10: 8.4029755 | N10: 1.3800953
C11: Chr4_L13 | D11: 0.13115958 | E11: TRANS_A_to_D_Chr4_L13 | F11: 2.1673248 | G11: TRANS_A_to_D_Chr4_L13 | H11: 0.042683361 | J11: TRANS_A_to_D_Chr4_L13 | L11: 0.13115958 | M11: 2.1673248 | N11: 0.042683361
A12: TRANS_A_to_D_Chr4_L15_2 | B12: 2.4 | C12: Chr4_L15_2 | D12: 2.2467636 | E12: TRANS_A_to_D_Chr4_L15_2 | F12: 6.7040132 | G12: TRANS_A_to_D_Chr4_L15_2 | H12: 1.2947286 | J12: TRANS_A_to_D_Chr4_L15_2 | K12: 2.4 | L12: 2.2467636 | M12: 6.7040132 | N12: 1.2947286
A13: TRANS_A_to_D_Chr7_990K | B13: 1.4 | C13: Chr7_990K | D13: 1.1424 | E13: TRANS_A_to_D_Chr7_990K | F13: 3.6183304 | G13: TRANS_A_to_D_Chr7_990K | H13: 0.23475848 | J13: TRANS_A_to_D_Chr7_990K | K13: 1.4 | L13: 1.1424 | M13: 3.6183304 | N13: 0.23475848
C14: Chr7_L03 | D14: 1.9083719 | E14: TRANS_A_to_D_Chr7_L03 | F14: 1.3499862 | G14: TRANS_A_to_D_Chr7_L03 | H14: 0.028455574 | J14: TRANS_A_to_D_Chr7_L03 | L14: 1.9083719 | M14: 1.3499862 | N14: 0.028455574
A15: TRANS_A_to_D_Chr7_L06 | B15: 0.5 | C15: Chr7_L06 | D15: 4.4764765 | E15: TRANS_A_to_D_Chr7_L06 | F15: 2.5714023 | G15: TRANS_A_to_D_Chr7_L06 | H15: 0.12805008 | J15: TRANS_A_to_D_Chr7_L06 | K15: 0.5 | L15: 4.4764765 | M15: 2.5714023 | N15: 0.12805008
C16: Chr7_L09 | D16: 0.61513844 | E16: TRANS_A_to_D_Chr7_L09 | F16: 2.6816053 | G16: TRANS_A_to_D_Chr7_L09 | H16: 0.064025041 | J16: TRANS_A_to_D_Chr7_L09 | L16: 0.61513844 | M16: 2.6816053 | N16: 0.064025041
A17: TRANS_A_to_D_Chr12_L01 | B17: 0.7 | C17: Chr12_L01 | D17: 1.7955747 | E17: TRANS_A_to_D_Chr12_L01 | F17: 1.2214161 | G17: TRANS_A_to_D_Chr12_L01 | H17: 0.25610016 | J17: TRANS_A_to_D_Chr12_L01 | K17: 0.7 | L17: 1.7955747 | M17: 1.2214161 | N17: 0.25610016
A18: TRANS_A_to_D_Chr12_L05 | B18: 2.2 | C18: Chr12_L05 | D18: 0.17575384 | E18: TRANS_A_to_D_Chr12_L05 | F18: 2.3969143 | G18: TRANS_A_to_D_Chr12_L05 | H18: 0.91057836 | J18: TRANS_A_to_D_Chr12_L05 | K18: 2.2 | L18: 0.17575384 | M18: 2.3969143 | N18: 0.91057836
A19: TRANS_A_to_D_Chr12_L07 | B19: 0.2 | C19: Chr12_L07 | D19: 0.46037013 | E19: TRANS_A_to_D_Chr12_L07 | F19: 1.092846 | G19: TRANS_A_to_D_Chr12_L07 | H19: 0.33435299 | J19: TRANS_A_to_D_Chr12_L07 | K19: 0.2 | L19: 0.46037013 | M19: 1.092846 | N19: 0.33435299
A20: TRANS_A_to_D_Chr12_L12 | B20: 0.5 | C20: Chr12_L12 | D20: 3.1556995 | E20: TRANS_A_to_D_Chr12_L12 | F20: 0.52346405 | G20: TRANS_A_to_D_Chr12_L12 | H20: 1.0101729 | J20: TRANS_A_to_D_Chr12_L12 | K20: 0.5 | L20: 3.1556995 | M20: 0.52346405 | N20: 1.0101729
A21: TRANS_A_to_D_Chr15_L01 | B21: 19 | C21: Chr15_L01 | D21: 2.2808651 | E21: TRANS_A_to_D_Chr15_L01 | F21: 6.7407475 | G21: TRANS_A_to_D_Chr15_L01 | H21: 3.3221882 | J21: TRANS_A_to_D_Chr15_L01 | K21: 19 | L21: 2.2808651 | M21: 6.7407475 | N21: 3.3221882
A22: TRANS_A_to_D_Chr15_L04 | B22: 0 | C22: Chr15_L04 | D22: 0.018362341 | E22: TRANS_A_to_D_Chr15_L04 | F22: 0.0091835798 | G22: TRANS_A_to_D_Chr15_L04 | H22: 0.028455574 | J22: TRANS_A_to_D_Chr15_L04 | K22: 0 | L22: 0.018362341 | M22: 0.0091835798 | N22: 0.028455574
A23: TRANS_A_to_D_Chr15_L15 | B23: 9.3 | C23: Chr15_L15 | D23: 0.8774576 | E23: TRANS_A_to_D_Chr15_L15 | F23: 0.14693728 | G23: TRANS_A_to_D_Chr15_L15 | H23: 4.7449669 | J23: TRANS_A_to_D_Chr15_L15 | K23: 9.3 | L23: 0.8774576 | M23: 0.14693728 | N23: 4.7449669
C24: Chr15_L17_2 | D24: 4.7230565 | E24: TRANS_A_to_D_Chr15_L17_2 | F24: 3.7836349 | G24: TRANS_A_to_D_Chr15_L17_2 | H24: 0.042683361 | J24: TRANS_A_to_D_Chr15_L17_2 | L24: 4.7230565 | M24: 3.7836349 | N24: 0.042683361
A25: TRANS_A_to_D_Chr15_L18 | B25: 6.7 | C25: Chr15_L18 | D25: 0.043282662 | E25: TRANS_A_to_D_Chr15_L18 | F25: 0.036734319 | G25: TRANS_A_to_D_Chr15_L18 | H25: 0.042683361 | J25: TRANS_A_to_D_Chr15_L18 | K25: 6.7 | L25: 0.043282662 | M25: 0.036734319 | N25: 0.042683361
A26: TRANS_A_to_D_NO_CUT | B26: 0 | C26: TRANS_A_to_D_UNCUTTABLE | D26: 5.9953045 | E26: TRANS_A_to_D_UNCUTTABLE | F26: 6.5570759 | G26: TRANS_A_to_D_UNCUTTABLE | H26: 1.9065234 | J26: TRANS_A_to_D_UNCUTTABLE | K26: 0 | L26: 5.9953045 | M26: 6.5570759 | N26: 1.9065234
A27: TRANS_C_to_B_Chr3_L02 | B27: 6.5 | C27: Chr3_L02 | D27: 0.54037748 | E27: TRANS_C_to_B_Chr3_L02 | F27: 1.0676157 | G27: TRANS_C_to_B_Chr3_L02 | H27: 60.917031 | J27: TRANS_C_to_B_Chr3_L02 | K27: 6.5 | L27: 0.54037748 | M27: 1.0676157 | N27: 60.917031
A28: TRANS_C_to_B_Chr3_L03 | B28: 0 | E28: TRANS_C_to_B_Chr3_L03 | F28: 28.825623 | G28: TRANS_C_to_B_Chr3_L03 | H28: 2.8384279 | J28: TRANS_C_to_B_Chr3_L03 | K28: 0 | M28: 28.825623 | N28: 2.8384279
C29: Chr3_L04 | D29: 2.7228729 | E29: TRANS_C_to_B_Chr3_L04 | F29: 28.825623 | G29: TRANS_C_to_B_Chr3_L04 | H29: 7.4235808 | J29: TRANS_C_to_B_Chr3_L04 | L29: 2.7228729 | M29: 28.825623 | N29: 7.4235808
A30: TRANS_C_to_B_Chr3_L18 | B30: 0.2 | C30: Chr3_L18 | D30: 0.01573915 | J30: TRANS_C_to_B_Chr3_L18 | K30: 0.2 | L30: 0.01573915
A31: TRANS_C_to_B_Chr4_L01 | B31: 1.5 | C31: Chr4_L01 | D31: 4.3951576 | E31: TRANS_C_to_B_Chr4_L01 | F31: 11.3879 | G31: TRANS_C_to_B_Chr4_L01 | H31: 29.257642 | J31: TRANS_C_to_B_Chr4_L01 | K31: 1.5 | L31: 4.3951576 | M31: 11.3879 | N31: 29.257642
A32: TRANS_C_to_B_Chr4_L03 | B32: 11.5 | C32: Chr4_L03 | D32: 3.4888449 | E32: TRANS_C_to_B_Chr4_L03 | F32: 3.5587189 | G32: TRANS_C_to_B_Chr4_L03 | H32: 116.59389 | J32: TRANS_C_to_B_Chr4_L03 | K32: 11.5 | L32: 3.4888449 | M32: 3.5587189 | N32: 116.59389
A33: TRANS_C_to_B_Chr4_L06_2 | B33: 5.9 | C33: Chr4_L06_2 | D33: 3.0848734 | E33: TRANS_C_to_B_Chr4_L06_2 | F33: 5.3380783 | G33: TRANS_C_to_B_Chr4_L06_2 | H33: 81.004367 | J33: TRANS_C_to_B_Chr4_L06_2 | K33: 5.9 | L33: 3.0848734 | M33: 5.3380783 | N33: 81.004367
A34: TRANS_C_to_B_Chr4_L10_2 | B34: 2.9 | C34: Chr4_L10_2 | D34: 0.75810238 | E34: TRANS_C_to_B_Chr4_L10_2 | F34: 92.170819 | G34: TRANS_C_to_B_Chr4_L10_2 | H34: 44.323144 | J34: TRANS_C_to_B_Chr4_L10_2 | K34: 2.9 | L34: 0.75810238 | M34: 92.170819 | N34: 44.323144 | P34: Put these data into R to make frequency and correlation plots
A35: TRANS_C_to_B_Chr4_L12_2 | B35: 1.5 | C35: Chr4_L12_2 | D35: 6.3743557 | E35: TRANS_C_to_B_Chr4_L12_2 | F35: 132.74021 | G35: TRANS_C_to_B_Chr4_L12_2 | H35: 10.480349 | J35: TRANS_C_to_B_Chr4_L12_2 | K35: 1.5 | L35: 6.3743557 | M35: 132.74021 | N35: 10.480349 | P35: break labels off into different columns
C36: Chr4_L13 | D36: 0.84991409 | E36: TRANS_C_to_B_Chr4_L13 | F36: 83.629893 | G36: TRANS_C_to_B_Chr4_L13 | H36: 0.87336245 | J36: TRANS_C_to_B_Chr4_L13 | L36: 0.84991409 | M36: 83.629893 | N36: 0.87336245
A37: TRANS_C_to_B_Chr4_L15_2 | B37: 1.4 | C37: Chr4_L15_2 | D37: 1.0794434 | E37: TRANS_C_to_B_Chr4_L15_2 | F37: 43.41637 | G37: TRANS_C_to_B_Chr4_L15_2 | H37: 29.912664 | J37: TRANS_C_to_B_Chr4_L15_2 | K37: 1.4 | L37: 1.0794434 | M37: 43.41637 | N37: 29.912664
A38: TRANS_C_to_B_Chr7_990K | B38: 0.5 | C38: Chr7_990K | D38: 1.1620739 | E38: TRANS_C_to_B_Chr7_990K | F38: 11.032028 | G38: TRANS_C_to_B_Chr7_990K | H38: 24.454148 | J38: TRANS_C_to_B_Chr7_990K | K38: 0.5 | L38: 1.1620739 | M38: 11.032028 | N38: 24.454148
C39: Chr7_L03 | D39: 0.11410884 | E39: TRANS_C_to_B_Chr7_L03 | F39: 2.4911032 | G39: TRANS_C_to_B_Chr7_L03 | H39: 0 | J39: TRANS_C_to_B_Chr7_L03 | L39: 0.11410884 | M39: 2.4911032 | N39: 0
A40: TRANS_C_to_B_Chr7_L06 | B40: 0.2 | C40: Chr7_L06 | D40: 5.3460646 | E40: TRANS_C_to_B_Chr7_L06 | F40: 16.014235 | G40: TRANS_C_to_B_Chr7_L06 | H40: 3.7117904 | J40: TRANS_C_to_B_Chr7_L06 | K40: 0.2 | L40: 5.3460646 | M40: 16.014235 | N40: 3.7117904
...

Sheet TRANS Fold Change
A1: Strain | B1: Chr III | C1: Chr VII | D1: Chr IV | E1: Chr XV
A2: TRANS_A_to_D_Chr3_L02 | B2: ='T120 aggregated TRANS'!K3/'T0 aggregated TRANS'!N3 -> 0.6 | C2: ='T120 aggregated TRANS'!L3/'T0 aggregated TRANS'!O3 -> 0.16707954 | D2: ='T120 aggregated TRANS'!M3/'T0 aggregated TRANS'!P3 -> 0.12549407 | E2: ='T120 aggregated TRANS'!N3/'T0 aggregated TRANS'!Q3 -> 0.8815052
A3: TRANS_A_to_D_Chr3_L03 | B3: ='T120 aggregated TRANS'!K4/'T0 aggregated TRANS'!N4 -> 0.5 | C3: ='T120 aggregated TRANS'!L4/'T0 aggregated TRANS'!O4 -> 0 | D3: ='T120 aggregated TRANS'!M4/'T0 aggregated TRANS'!P4 -> 3.5240385 | E3: ='T120 aggregated TRANS'!N4/'T0 aggregated TRANS'!Q4 -> 0.020618557
A4: TRANS_A_to_D_Chr3_L04 | B4: ='T120 aggregated TRANS'!K5/'T0 aggregated TRANS'!N5 -> 0 | C4: ='T120 aggregated TRANS'!L5/'T0 aggregated TRANS'!O5 -> 1.4134744 | D4: ='T120 aggregated TRANS'!M5/'T0 aggregated TRANS'!P5 -> 1.381043 | E4: ='T120 aggregated TRANS'!N5/'T0 aggregated TRANS'!Q5 -> 0.018404908
A5: TRANS_A_to_D_Chr4_L01 | B5: ='T120 aggregated TRANS'!K6/'T0 aggregated TRANS'!N6 -> 0.28 | C5: ='T120 aggregated TRANS'!L6/'T0 aggregated TRANS'!O6 -> 0.51982475 | D5: ='T120 aggregated TRANS'!M6/'T0 aggregated TRANS'!P6 -> 0.11956522 | E5: ='T120 aggregated TRANS'!N6/'T0 aggregated TRANS'!Q6 -> 1.3989637
A6: TRANS_A_to_D_Chr4_L03 | B6: ='T120 aggregated TRANS'!K7/'T0 aggregated TRANS'!N7 -> 1.7419355 | C6: ='T120 aggregated TRANS'!L7/'T0 aggregated TRANS'!O7 -> 0.65316518 | D6: ='T120 aggregated TRANS'!M7/'T0 aggregated TRANS'!P7 -> 0.16225166 | E6: ='T120 aggregated TRANS'!N7/'T0 aggregated TRANS'!Q7 -> 2.460177
A7: TRANS_A_to_D_Chr4_L06_2 | B7: ='T120 aggregated TRANS'!K8/'T0 aggregated TRANS'!N8 -> 2.6 | C7: ='T120 aggregated TRANS'!L8/'T0 aggregated TRANS'!O8 -> 0.44398294 | D7: ='T120 aggregated TRANS'!M8/'T0 aggregated TRANS'!P8 -> 0.1590106 | E7: ='T120 aggregated TRANS'!N8/'T0 aggregated TRANS'!Q8 -> 1.3890909
A8: TRANS_A_to_D_Chr4_L10_2 | B8: ='T120 aggregated TRANS'!K9/'T0 aggregated TRANS'!N9 -> 1.3125 | C8: ='T120 aggregated TRANS'!L9/'T0 aggregated TRANS'!O9 -> 0.2494976 | D8: ='T120 aggregated TRANS'!M9/'T0 aggregated TRANS'!P9 -> 2.5217391 | E8: ='T120 aggregated TRANS'!N9/'T0 aggregated TRANS'!Q9 -> 1.5809129
A9: TRANS_A_to_D_Chr4_L12_2 | B9: ='T120 aggregated TRANS'!K10/'T0 aggregated TRANS'!N10 -> 1.0344828 | C9: ='T120 aggregated TRANS'!L10/'T0 aggregated TRANS'!O10 -> 2.7830621 | D9: ='T120 aggregated TRANS'!M10/'T0 aggregated TRANS'!P10 -> 9.9456522 | E9: ='T120 aggregated TRANS'!N10/'T0 aggregated TRANS'!Q10 -> 0.79508197
A10: TRANS_A_to_D_Chr4_L13 | B10: ='T120 aggregated TRANS'!K11/'T0 aggregated TRANS'!N11 -> 0 | C10: ='T120 aggregated TRANS'!L11/'T0 aggregated TRANS'!O11 -> 0.067412432 | D10: ='T120 aggregated TRANS'!M11/'T0 aggregated TRANS'!P11 -> 0.55399061 | E10: ='T120 aggregated TRANS'!N11/'T0 aggregated TRANS'!Q11 -> 0.0071258907
A11: TRANS_A_to_D_Chr4_L15_2 | B11: ='T120 aggregated TRANS'!K12/'T0 aggregated TRANS'!N12 -> 12 | C11: ='T120 aggregated TRANS'!L12/'T0 aggregated TRANS'!O12 -> 2.4085306 | D11: ='T120 aggregated TRANS'!M12/'T0 aggregated TRANS'!P12 -> 2.7443609 | E11: ='T120 aggregated TRANS'!N12/'T0 aggregated TRANS'!Q12 -> 0.95789474
A12: TRANS_A_to_D_Chr7_990K | B12: ='T120 aggregated TRANS'!K13/'T0 aggregated TRANS'!N13 -> 4.6666667 | C12: ='T120 aggregated TRANS'!L13/'T0 aggregated TRANS'!O13 -> 0.32227704 | D12: ='T120 aggregated TRANS'!M13/'T0 aggregated TRANS'!P13 -> 1.3046358 | E12: ='T120 aggregated TRANS'!N13/'T0 aggregated TRANS'!Q13 -> 0.35869565
A13: TRANS_A_to_D_Chr7_L03 | B13: ='T120 aggregated TRANS'!K14/'T0 aggregated TRANS'!N14 -> #DIV/0! | C13: ='T120 aggregated TRANS'!L14/'T0 aggregated TRANS'!O14 -> 0.77828385 | D13: ='T120 aggregated TRANS'!M14/'T0 aggregated TRANS'!P14 -> 0.46964856 | E13: ='T120 aggregated TRANS'!N14/'T0 aggregated TRANS'!Q14 -> 0.0067001675
... A46: TRANS_C_to_B_Chr15_L01 | B46: ='T120 aggregated TRANS'!K47/'T0 aggregated TRANS'!N47 -> #DIV/0! | C46: ='T120 aggregated TRANS'!L47/'T0 aggregated TRANS'!O47 -> #DIV/0! | D46: ='T120 aggregated TRANS'!M47/'T0 aggregated TRANS'!P47 -> #DIV/0! | E46: ='T120 aggregated TRANS'!N47/'T0 aggregated TRANS'!Q47 -> 231.5
A47: TRANS_C_to_B_Chr15_L04 | B47: ='T120 aggregated TRANS'!K48/'T0 aggregated TRANS'!N48 -> 0 | C47: ='T120 aggregated TRANS'!L48/'T0 aggregated TRANS'!O48 -> 0 | D47: ='T120 aggregated TRANS'!M48/'T0 aggregated TRANS'!P48 -> 0 | E47: ='T120 aggregated TRANS'!N48/'T0 aggregated TRANS'!Q48 -> 0 | F47: N/A
A48: TRANS_C_to_B_Chr15_L15 | B48: ='T120 aggregated TRANS'!K49/'T0 aggregated TRANS'!N49 -> #DIV/0! | C48: ='T120 aggregated TRANS'!L49/'T0 aggregated TRANS'!O49 -> #DIV/0! | D48: ='T120 aggregated TRANS'!M49/'T0 aggregated TRANS'!P49 -> 19.125 | E48: ='T120 aggregated TRANS'!N49/'T0 aggregated TRANS'!Q49 -> 147.5
A49: TRANS_C_to_B_Chr15_L17_2 | B49: ='T120 aggregated TRANS'!K50/'T0 aggregated TRANS'!N50 -> #DIV/0! | C49: ='T120 aggregated TRANS'!L50/'T0 aggregated TRANS'!O50 -> #DIV/0! | D49: ='T120 aggregated TRANS'!M50/'T0 aggregated TRANS'!P50 -> 61 | E49: ='T120 aggregated TRANS'!N50/'T0 aggregated TRANS'!Q50 -> 0.33333333
A50: TRANS_C_to_B_Chr15_L18 | B50: ='T120 aggregated TRANS'!K51/'T0 aggregated TRANS'!N51 -> 0 | C50: ='T120 aggregated TRANS'!L51/'T0 aggregated TRANS'!O51 -> #DIV/0! | D50: ='T120 aggregated TRANS'!M51/'T0 aggregated TRANS'!P51 -> 0 | E50: ='T120 aggregated TRANS'!N51/'T0 aggregated TRANS'!Q51 -> 0.095238095
A51: TRANS_C_to_B_UNCUTTABLE | B51: ='T120 aggregated TRANS'!K52/'T0 aggregated TRANS'!N52 -> #DIV/0! | C51: ='T120 aggregated TRANS'!L52/'T0 aggregated TRANS'!O52 -> #DIV/0! | D51: ='T120 aggregated TRANS'!M52/'T0 aggregated TRANS'!P52 -> #DIV/0! | E51: ='T120 aggregated TRANS'!N52/'T0 aggregated TRANS'!Q52 -> #DIV/0!
E53: 2 fold increase or greater
E54: 2 fold decrease or greater

Sheet Sheet7
A1: Strain | B1: Chr III | C1: Chr VII | D1: Chr IV | E1: Chr XV
A2: TRANS_A_to_D_Chr3_L02 | B2: 0.6 | C2: 0.16707954 | D2: 0.12549407 | E2: 0.8815052
A3: TRANS_A_to_D_Chr3_L03 | B3: 0.5 | C3: 0 | D3: 3.5240385 | E3: 0.020618557
A4: TRANS_A_to_D_Chr3_L04 | B4: 0 | C4: 1.4134744 | D4: 1.381043 | E4: 0.018404908
A5: TRANS_A_to_D_Chr4_L01 | B5: 0.28 | C5: 0.51982475 | D5: 0.11956522 | E5: 1.3989637
A6: TRANS_A_to_D_Chr4_L03 | B6: 1.7419355 | C6: 0.65316518 | D6: 0.16225166 | E6: 2.460177
A7: TRANS_A_to_D_Chr4_L06_2 | B7: 2.6 | C7: 0.44398294 | D7: 0.1590106 | E7: 1.3890909
A8: TRANS_A_to_D_Chr4_L10_2 | B8: 1.3125 | C8: 0.2494976 | D8: 2.5217391 | E8: 1.5809129
A9: TRANS_A_to_D_Chr4_L12_2 | B9: 1.0344828 | C9: 2.7830621 | D9: 9.9456522 | E9: 0.79508197
A10: TRANS_A_to_D_Chr4_L13 | B10: 0 | C10: 0.067412432 | D10: 0.55399061 | E10: 0.0071258907
A11: TRANS_A_to_D_Chr4_L15_2 | B11: 12 | C11: 2.4085306 | D11: 2.7443609 | E11: 0.95789474
A12: TRANS_A_to_D_Chr7_990K | B12: 4.6666667 | C12: 0.32227704 | D12: 1.3046358 | E12: 0.35869565
A13: TRANS_A_to_D_Chr7_L03 | B13: #DIV/0! | C13: 0.77828385 | D13: 0.46964856 | E13: 0.0067001675
A14: TRANS_A_to_D_Chr7_L06 | B14: #DIV/0! | C14: 4.7987828 | D14: 2.6168224 | E14: 0.075
A15: TRANS_A_to_D_Chr7_L09 | B15: #DIV/0! | C15: #DIV/0! | D15: 0.50694444 | E15: 0.013215859
A16: TRANS_A_to_D_Chr12_L01 | B16: 0.4375 | C16: 0.52224777 | D16: 0.44186047 | E16: 0.23225806
A17: TRANS_A_to_D_Chr12_L05 | B17: 0.39285714 | C17: 0.067288613 | D17: 1.1012658 | E17: 0.72316384
A18: TRANS_A_to_D_Chr12_L07 | B18: 0.125 | C18: 0.26171344 | D18: 0.33521127 | E18: 0.078991597
A19: TRANS_A_to_D_Chr12_L12 | B19: 0.22727273 | C19: 1.3929629 | D19: 0.069512195 | E19: 0.041028604
A20: TRANS_A_to_D_Chr15_L01 | B20: 2.2352941 | C20: 1.3802913 | D20: 2.6690909 | E20: 0.70331325
A21: TRANS_A_to_D_Chr15_L04 | B21: 0 | C21: 0.34447753 | D21: 0.2 | E21: 2
A22: TRANS_A_to_D_Chr15_L15 | B22: 1 | C22: 1.3168884 | D22: 0.03712297 | E22: 2.9126638
A23: TRANS_A_to_D_Chr15_L17_2 | B23: 0 | C23: 3.2219833 | D23: 0.73440285 | E23: 0.028571429
A24: TRANS_A_to_D_Chr15_L18 | B24: #DIV/0! | C24: 0.023199507 | D24: 0.10526316 | E24: 6
A25: TRANS_C_to_B_Chr3_L02 | B25: 1.2264151 | C25: 2.0274963 | D25: 0.1875 | E25: 5.3653846
A26: TRANS_C_to_B_Chr3_L03 | B26: #DIV/0! | C26: #DIV/0! | D26: 11.571429 | E26: 2.6
A27: TRANS_C_to_B_Chr3_L04 | B27: #DIV/0! | C27: 2.4917608 | D27: 2.25 | E27: 2.8333333
A28: TRANS_C_to_B_Chr3_L18 | B28: 2 | C28: 0.1968443 | D28: #DIV/0! | E28: #DIV/0!
A29: TRANS_C_to_B_Chr4_L01 | B29: 0.9375 | C29: 9.1614618 | D29: 5.3333333 | E29: 9.5714286
A30: TRANS_C_to_B_Chr4_L03 | B30: 4.4230769 | C30: 7.7000859 | D30: 0.625 | E30: 19.071429
A32: TRANS_C_to_B_Chr4_L10_2 | B32: 2.0714286 | C32: 1.2929092 | D32: 32.375 | E32: 7.5185185
A33: TRANS_C_to_B_Chr4_L12_2 | B33: 3 | C33: 2.7490325 | D33: 19.631579 | E33: 9.6
A35: TRANS_C_to_B_Chr4_L15_2 | B35: 4.6666667 | C35: 5.0625894 | D35: 3.05 | E35: 27.4
A36: TRANS_C_to_B_Chr7_990K | B36: 1.6666667 | C36: 0.9909321 | D36: 3.1 | E36: 5.6
A37: TRANS_C_to_B_Chr7_L03 | B37: #DIV/0! | C37: 0.23785353 | D37: 1.4 | E37: 0
A38: TRANS_C_to_B_Chr7_L06 | B38: #DIV/0! | C38: 10.029217 | D38: 4.0909091 | E38: 0.22972973
A39: TRANS_C_to_B_Chr7_L09 | B39: #DIV/0! | C39: 5.7412921 | D39: 0 | E39: 2.3333333
A40: TRANS_C_to_B_Chr7_L17_2 | B40: 0 | C40: 19.832063 | D40: 0 | E40: 0
A41: TRANS_C_to_B_Chr12_L01 | B41: 0.074074074 | C41: 1.7420721 | D41: 2.92 | E41: 10
A42: TRANS_C_to_B_Chr12_L05 | B42: 4.5 | C42: 3.3832614 | D42: 24.8 | E42: 12.2
...
